<?xml version="1.0"?>
<robot name="simple_arm" xmlns:xacro="http://www.ros.org/wiki/xacro">

  <link name="base_link">
    <visual>
      <geometry>
        <box size="0.3 0.3 0.1"/>
      </geometry>
      <material name="blue"/>
    </visual>
  </link>

  <link name="link1">
    <visual>
      <geometry>
        <cylinder radius="0.05" length="0.5"/>
      </geometry>
      <material name="red"/>
    </visual>
  </link>

  <link name="link2">
    <visual>
      <geometry>
        <cylinder radius="0.05" length="0.3"/>
      </geometry>
      <material name="green"/>
    </visual>
  </link>

  <joint name="joint1" type="revolute">
    <parent link="base_link"/>
    <child link="link1"/>
    <origin xyz="0 0 0.05" rpy="0 0 0"/>
    <axis xyz="0 0 1"/>
    <limit lower="-1.57" upper="1.57" effort="5" velocity="1"/>
  </joint>

  <joint name="joint2" type="revolute">
    <parent link="link1"/>
    <child link="link2"/>
    <origin xyz="0 0 0.5" rpy="0 0 0"/>
    <axis xyz="0 1 0"/>
    <limit lower="-1.57" upper="1.57" effort="5" velocity="1"/>
  </joint>

</robot>
